Workbook

Sheet 01_실습안내
A1: AI와 함께하는 스마트 엑셀 - 학생 실습
A2: 상황 | B2: 3개 지점의 3개월 카페 매출 데이터를 AI로 진단·정제·분석합니다.
A3: 미션1 | B3: AI에게 데이터 품질 문제를 진단받으세요.
A4: 미션2 | B4: XLOOKUP, IFERROR, SUMIFS 등 필요한 수식을 AI에게 요청하고 검증하세요.
A5: 미션3 | B5: 불필요한 행·중복·형식 문제를 정리해 「05_정제데이터」 시트를 완성하세요. (Power Query는 강사 시연으로만 소개)
A6: 미션4 | B6: 피벗테이블로 지점·월·상품분류별 매출을 분석하세요.
A7: 미션5 | B7: 차트와 AI 보고서를 작성하세요: 현황 → 인사이트 → 추가 확인사항.
A8: AI 규칙 | B8: 데이터에 없는 원인이나 사실은 추측하지 말고 계산 결과는 Excel에서 검증하세요.

Sheet 02_매출원본
A1: 주문일자 | B1: 지점코드 | C1: 지점명 | D1: 상품코드 | E1: 상품명 | F1: 수량 | G1: 판매단가 | H1: 매출액 | I1: 결제수단 | J1: 담당자 | K1: 주문상태 | L1: 비고
A2: 46091 | B2: S001 | C2: 신구점 | D2: P005 | E2: 녹차라떼 | F2: 3 | G2: 4500 | H2: 13500 | I2: 카드 | J2: 한지우 | K2: 판매
A3: 46129 | B3: S002 | C3: 성남점 | D3: P002 | E3: 카페라떼 | F3: 1 | G3: 4000 | H3: 4000 | I3: 간편결제 | J3: 한지우 | K3: 판매
A4: 46088 | B4: S002 | C4: 성남점 | D4: P007 | E4: 치즈케이크 | F4: 2 | G4: 5000 | H4: 10000 | I4: 카드 | J4: 정다은 | K4: 판매
A5: 46139 | B5: S002 | C5: 성남점 | D5: P001 | E5: 아메리카노 | F5: 3 | G5: 3000 | H5: 9000 | I5: 간편결제 | J5: 박서연 | K5: 판매
A6: 46112 | B6: S001 | C6: 신구점 | D6: P003 | E6: 바닐라라떼 | F6: 4 | G6: 4500 | H6: 18000 | I6: 간편결제 | J6: 박서연 | K6: 판매
A7: 46085 | B7: S003 | C7: 용인점 | D7: P001 | E7: 아메리카노 | F7: 1 | G7: 3000 | H7: 3000 | I7: 현금 | J7: 한지우 | K7: 판매
A8: 46104 | B8: S002 | C8: 성남점 | D8: P001 | E8: 아메리카노 | G8: 3000 | H8: 3000 | I8: 카드 | J8: 이서준 | K8: 판매
A9: 46106 | B9: S001 | C9: 신구점 | D9: P003 | E9: 바닐라라떼 | F9: 1 | G9: 4500 | H9: 4500 | I9: 카드 | J9: 최지훈 | K9: 판매
A10: 46111 | B10: S001 | C10: 신구점 | D10: P008 | E10: 크루아상 | F10: 2 | G10: 3500 | H10: 7000 | I10: 카드 | J10: 한지우 | K10: 판매
A11: 46126 | B11: S003 | C11: 용인점 | D11: P001 | E11: 아메리카노 | F11: 2 | G11: 3000 | H11: 6000 | I11: 간편결제 | J11: 이서준 | K11: 판매
A12: 46109 | B12: S002 | C12: 성남 점 | D12: P003 | E12: 바닐라라떼 | F12: 2 | G12: 4500 | H12: 9000 | I12: 카드 | J12: 김민지 | K12: 판매
A13: 46136 | B13: S002 | C13: 성남점 | D13: P003 | E13: 바닐라라떼 | F13: 5 | G13: 4500 | H13: 22500 | I13: 현금 | J13: 박서연 | K13: 판매
A14: 46150 | B14: S002 | C14: 성남점 | D14: P009 | E14: 샌드위치 | F14: 4 | G14: 5500 | H14: 22000 | I14: 현금 | J14: 박서연 | K14: 판매
A15: 46103 | B15: S001 | C15: 신구점 | D15: P001 | E15: 아메리카노 | F15: 1 | G15: 3000 | H15: 3000 | I15: 간편결제 | J15: 김민지 | K15: 판매
A16: 46144 | B16: S001 | C16: 신구점 | D16: P002 | E16: 카페 라떼 | F16: 2 | G16: 4000 | H16: 8000 | I16: 간편결제 | J16: 김민지 | K16: 판매
A17: 46125 | B17: S001 | C17: 신구점 | D17: P004 | E17: 카라멜마끼아또 | F17: 2 | G17: 4800 | H17: 9600 | I17: 현금 | J17: 정다은 | K17: 취소
A18: 46131 | B18: S001 | C18: 신구점 | D18: P001 | E18: 아메리카노 | F18: 3 | G18: 3000 | H18: 9000 | I18: 현금 | J18: 박서연 | K18: 판매
A19: 46165 | B19: S001 | C19: 신구점 | D19: P010 | E19: 베이글 | F19: 2 | G19: 4000 | H19: 8000 | I19: 카드 | J19: 박서연 | K19: 판매
A20: 46160 | B20: S002 | C20: 성남점 | D20: P001 | E20: 아메리카노 | F20: 1 | G20: 3000 | H20: 3000 | I20: 간편결제 | J20: 최지훈 | K20: 판매
A21: 46126 | B21: S001 | C21: 신구점 | D21: P004 | E21: 카라멜마끼아또 | F21: 4 | G21: 4800 | H21: 19200 | I21: 현금 | K21: 판매
A22: 46138 | B22: S003 | C22: 용인점 | D22: P008 | E22: 크루아상 | F22: 2 | G22: 3500 | H22: 7000 | I22: 카드 | J22: 최지훈 | K22: 판매
A23: 46141 | B23: S003 | C23: 용인점 | D23: P005 | E23: 녹차라떼 | F23: 1 | G23: 4500 | H23: 4500 | I23: 간편결제 | J23: 최지훈 | K23: 판매
A24: 2026/04/21 | B24: S003 | C24: 용인점 | D24: P001 | E24: 아메리카노 | F24: 1 | G24: 3000 | H24: 3000 | I24: 카드 | J24: 김민지 | K24: 판매
A25: 46130 | B25: S001 | C25: 신구점 | D25: P002 | E25: 카페라떼 | F25: 2 | G25: 4000 | H25: 8000 | I25: 카드 | J25: 한지우 | K25: 판매
A26: 46141 | B26: S001 | C26: 신구점 | D26: P001 | E26: 아메리카노 | F26: 2 | G26: 3000 | H26: 6000 | I26: 간편결제 | J26: 박서연 | K26: 판매
A27: 46149 | B27: S001 | C27: 신구점 | D27: P007 | E27: 치즈케이크 | F27: 2 | G27: 5000 | H27: 10000 | I27: 간편결제 | J27: 김민지 | K27: 취소
A28: 46163 | B28: S002 | C28: 성남지점 | D28: P008 | E28: 크루아상 | F28: 2 | G28: 3500 | H28: 7000 | I28: 간편결제 | J28: 정다은 | K28: 취소
A29: 46095 | B29: S003 | C29: 용인점 | D29: P007 | E29: 치즈케이크 | F29: 4 | G29: 5000 | H29: 20000 | I29: 현금 | J29: 정다은 | K29: 판매
A30: 46115 | B30: S002 | C30: 성남점 | D30: P004 | E30: 카라멜마끼아또 | F30: 3 | G30: 4800 | H30: 14400 | I30: 간편결제 | J30: 김민지 | K30: 판매
A31: 46161 | B31: S001 | C31: 신구점 | D31: P001 | E31: 아메리카노 | F31: 2 | G31: 3000 | H31: 6000 | I31: 카드 | J31: 박서연 | K31: 판매
A32: 46119 | B32: S002 | C32: 성남점 | D32: P006 | E32: 초코라떼 | F32: 1 | G32: 4500 | H32: 4500 | I32: 현금 | J32: 이서준 | K32: 판매
A33: 46088 | B33: S002 | C33: 성남점 | D33: P005 | E33: 녹차라떼 | F33: 1 | G33: 4500 | H33: 4500 | I33: 간편결제 | J33: 정다은 | K33: 판매
A34: 46109 | B34: S003 | C34: 용인점 | D34: P007 | E34: 치즈케이크 | F34: 4 | G34: 5000 | H34: 20000 | I34: 카드 | J34: 정다은 | K34: 판매
A35: 46133 | B35: S002 | C35: 성남점 | D35: P001 | E35: 아메리카노 | F35: 2 | G35: 3000 | H35: 6000 | I35: 간편결제 | J35: 김민지 | K35: 판매
A36: 46090 | B36: S003 | C36: 용인점 | D36: P004 | E36: 카라멜마끼아또 | F36: 2 | G36: 4800 | H36: 9600 | I36: 간편결제 | J36: 김민지 | K36: 판매
A37: 46149 | B37: S002 | C37: 성남점 | D37: P008 | E37: 크루아상 | F37: 1 | G37: 3500 | H37: 3500 | J37: 최지훈 | K37: 판매
A38: 46168 | B38: S002 | C38: 성남점 | D38: P010 | E38: 베이글 | F38: 1 | G38: 4000 | H38: 4000 | I38: 현금 | J38: 박서연 | K38: 판매
A39: 46153 | B39: S001 | C39: 신구점 | D39: P010 | E39: 베이글 | F39: 1 | G39: 4000 | H39: 4000 | I39: 카드 | J39: 한지우 | K39: 판매
A40: 46108 | B40: S001 | C40: 신구점 | D40: P010 | E40: 베이글 | F40: 2 | G40: 4000 | H40: 8000 | I40: 현금 | J40: 박서연 | K40: 취소
...

Sheet 03_상품Master
A1: 상품코드 | B1: 상품명 | C1: 상품분류 | D1: 정상판매가
A2: P001 | B2: 아메리카노 | C2: 커피 | D2: 3000
A3: P002 | B3: 카페라떼 | C3: 커피 | D3: 4000
A4: P003 | B4: 바닐라라떼 | C4: 커피 | D4: 4500
A5: P004 | B5: 카라멜마끼아또 | C5: 커피 | D5: 4800
A6: P005 | B6: 녹차라떼 | C6: 논커피 | D6: 4500
A7: P006 | B7: 초코라떼 | C7: 논커피 | D7: 4500
A8: P007 | B8: 치즈케이크 | C8: 디저트 | D8: 5000
A9: P008 | B9: 크루아상 | C9: 디저트 | D9: 3500
A10: P009 | B10: 샌드위치 | C10: 푸드 | D10: 5500
A11: P010 | B11: 베이글 | C11: 푸드 | D11: 4000

Sheet 04_지점Master
A1: 지점코드 | B1: 지점명 | C1: 지역
A2: S001 | B2: 신구점 | C2: 성남시
A3: S002 | B3: 성남점 | C3: 성남시
A4: S003 | B4: 용인점 | C4: 용인시

Sheet 05_정제데이터
A1: 주문일자 | B1: 지점코드 | C1: 지점명 | D1: 상품코드 | E1: 상품명 | F1: 수량 | G1: 판매단가 | H1: 매출액 | I1: 결제수단 | J1: 담당자 | K1: 주문상태 | L1: 비고 | M1: 상품분류 | N1: 매출검증 | O1: 중복키 | P1: 중복여부 | Q1: 날짜변환 | R1: 지점명2 | S1: 상품코드3 | T1: 상품명4 | U1: 매출액5 | W1: 3월 신구점 판매
A2: 46091 | B2: S001 | C2: 신구점 | D2: P005 | E2: 녹차라떼 | F2: 3 | G2: 4500 | H2: 13500 | I2: 카드 | J2: 한지우 | K2: 판매 | M2: =_xlfn.XLOOKUP(D2,'03_상품Master'!$A$2:$A$11,'03_상품Master'!$C$2:$C$11,"확인필요") -> 논커피 | N2: =IF(COUNT(F2:H2)<3, "값확인", IF(F2*G2=H2, "정상", "검토필요")) -> 정상 | O2: =_xlfn.TEXTJOIN("|",FALSE,A2:L2) -> 46091|S001|신구점|P005|녹차라떼|3|4500|13500|카드|한지우|판매| | P2: =IF(COUNTIF(O2:O290,O2)>1,"중복", "") | Q2: =IFERROR(IF(ISNUMBER(A2), A2,DATEVALUE(SUBSTITUTE(A2,".","-")))," 확인필요") -> 46091 | W2: =SUMIFS(H:H,C:C,"신구점",K:K,"판매",A:A,">="&DATE(2026,3,1), A:A,"<"&DATE(2026,4,1)) -> 298300
A3: 46129 | B3: S002 | C3: 성남점 | D3: P002 | E3: 카페라떼 | F3: 1 | G3: 4000 | H3: 4000 | I3: 간편결제 | J3: 한지우 | K3: 판매 | M3: =_xlfn.XLOOKUP(D3,'03_상품Master'!$A$2:$A$11,'03_상품Master'!$C$2:$C$11,"확인필요") -> 커피 | N3: =IF(COUNT(F3:H3)<3, "값확인", IF(F3*G3=H3, "정상", "검토필요")) -> 정상 | O3: =_xlfn.TEXTJOIN("|",FALSE,A3:L3) -> 46129|S002|성남점|P002|카페라떼|1|4000|4000|간편결제|한지우|판매| | P3: =IF(COUNTIF(O3:O291,O3)>1,"중복", "") | Q3: =IFERROR(IF(ISNUMBER(A3), A3,DATEVALUE(SUBSTITUTE(A3,".","-")))," 확인필요") -> 46129
A4: 46088 | B4: S002 | C4: 성남점 | D4: P007 | E4: 치즈케이크 | F4: 2 | G4: 5000 | H4: 10000 | I4: 카드 | J4: 정다은 | K4: 판매 | M4: =_xlfn.XLOOKUP(D4,'03_상품Master'!$A$2:$A$11,'03_상품Master'!$C$2:$C$11,"확인필요") -> 디저트 | N4: =IF(COUNT(F4:H4)<3, "값확인", IF(F4*G4=H4, "정상", "검토필요")) -> 정상 | O4: =_xlfn.TEXTJOIN("|",FALSE,A4:L4) -> 46088|S002|성남점|P007|치즈케이크|2|5000|10000|카드|정다은|판매| | P4: =IF(COUNTIF(O4:O292,O4)>1,"중복", "") | Q4: =IFERROR(IF(ISNUMBER(A4), A4,DATEVALUE(SUBSTITUTE(A4,".","-")))," 확인필요") -> 46088
A5: 46139 | B5: S002 | C5: 성남점 | D5: P001 | E5: 아메리카노 | F5: 3 | G5: 3000 | H5: 9000 | I5: 간편결제 | J5: 박서연 | K5: 판매 | M5: =_xlfn.XLOOKUP(D5,'03_상품Master'!$A$2:$A$11,'03_상품Master'!$C$2:$C$11,"확인필요") -> 커피 | N5: =IF(COUNT(F5:H5)<3, "값확인", IF(F5*G5=H5, "정상", "검토필요")) -> 정상 | O5: =_xlfn.TEXTJOIN("|",FALSE,A5:L5) -> 46139|S002|성남점|P001|아메리카노|3|3000|9000|간편결제|박서연|판매| | P5: =IF(COUNTIF(O5:O293,O5)>1,"중복", "") | Q5: =IFERROR(IF(ISNUMBER(A5), A5,DATEVALUE(SUBSTITUTE(A5,".","-")))," 확인필요") -> 46139
A6: 46112 | B6: S001 | C6: 신구점 | D6: P003 | E6: 바닐라라떼 | F6: 4 | G6: 4500 | H6: 18000 | I6: 간편결제 | J6: 박서연 | K6: 판매 | M6: =_xlfn.XLOOKUP(D6,'03_상품Master'!$A$2:$A$11,'03_상품Master'!$C$2:$C$11,"확인필요") -> 커피 | N6: =IF(COUNT(F6:H6)<3, "값확인", IF(F6*G6=H6, "정상", "검토필요")) -> 정상 | O6: =_xlfn.TEXTJOIN("|",FALSE,A6:L6) -> 46112|S001|신구점|P003|바닐라라떼|4|4500|18000|간편결제|박서연|판매| | P6: =IF(COUNTIF(O6:O294,O6)>1,"중복", "") | Q6: =IFERROR(IF(ISNUMBER(A6), A6,DATEVALUE(SUBSTITUTE(A6,".","-")))," 확인필요") -> 46112
A7: 46085 | B7: S003 | C7: 용인점 | D7: P001 | E7: 아메리카노 | F7: 1 | G7: 3000 | H7: 3000 | I7: 현금 | J7: 한지우 | K7: 판매 | M7: =_xlfn.XLOOKUP(D7,'03_상품Master'!$A$2:$A$11,'03_상품Master'!$C$2:$C$11,"확인필요") -> 커피 | N7: =IF(COUNT(F7:H7)<3, "값확인", IF(F7*G7=H7, "정상", "검토필요")) -> 정상 | O7: =_xlfn.TEXTJOIN("|",FALSE,A7:L7) -> 46085|S003|용인점|P001|아메리카노|1|3000|3000|현금|한지우|판매| | P7: =IF(COUNTIF(O7:O295,O7)>1,"중복", "") | Q7: =IFERROR(IF(ISNUMBER(A7), A7,DATEVALUE(SUBSTITUTE(A7,".","-")))," 확인필요") -> 46085
A8: 46106 | B8: S001 | C8: 신구점 | D8: P003 | E8: 바닐라라떼 | F8: 1 | G8: 4500 | H8: 4500 | I8: 카드 | J8: 최지훈 | K8: 판매 | M8: =_xlfn.XLOOKUP(D8,'03_상품Master'!$A$2:$A$11,'03_상품Master'!$C$2:$C$11,"확인필요") -> 커피 | N8: =IF(COUNT(F8:H8)<3, "값확인", IF(F8*G8=H8, "정상", "검토필요")) -> 정상 | O8: =_xlfn.TEXTJOIN("|",FALSE,A8:L8) -> 46106|S001|신구점|P003|바닐라라떼|1|4500|4500|카드|최지훈|판매| | P8: =IF(COUNTIF(O8:O297,O8)>1,"중복", "") | Q8: =IFERROR(IF(ISNUMBER(A8), A8,DATEVALUE(SUBSTITUTE(A8,".","-")))," 확인필요") -> 46106
A9: 46111 | B9: S001 | C9: 신구점 | D9: P008 | E9: 크루아상 | F9: 2 | G9: 3500 | H9: 7000 | I9: 카드 | J9: 한지우 | K9: 판매 | M9: =_xlfn.XLOOKUP(D9,'03_상품Master'!$A$2:$A$11,'03_상품Master'!$C$2:$C$11,"확인필요") -> 디저트 | N9: =IF(COUNT(F9:H9)<3, "값확인", IF(F9*G9=H9, "정상", "검토필요")) -> 정상 | O9: =_xlfn.TEXTJOIN("|",FALSE,A9:L9) -> 46111|S001|신구점|P008|크루아상|2|3500|7000|카드|한지우|판매| | P9: =IF(COUNTIF(O9:O298,O9)>1,"중복", "") | Q9: =IFERROR(IF(ISNUMBER(A9), A9,DATEVALUE(SUBSTITUTE(A9,".","-")))," 확인필요") -> 46111
A10: 46126 | B10: S003 | C10: 용인점 | D10: P001 | E10: 아메리카노 | F10: 2 | G10: 3000 | H10: 6000 | I10: 간편결제 | J10: 이서준 | K10: 판매 | M10: =_xlfn.XLOOKUP(D10,'03_상품Master'!$A$2:$A$11,'03_상품Master'!$C$2:$C$11,"확인필요") -> 커피 | N10: =IF(COUNT(F10:H10)<3, "값확인", IF(F10*G10=H10, "정상", "검토필요")) -> 정상 | O10: =_xlfn.TEXTJOIN("|",FALSE,A10:L10) -> 46126|S003|용인점|P001|아메리카노|2|3000|6000|간편결제|이서준|판매| | P10: =IF(COUNTIF(O10:O299,O10)>1,"중복", "") | Q10: =IFERROR(IF(ISNUMBER(A10), A10,DATEVALUE(SUBSTITUTE(A10,".","-")))," 확인필요") -> 46126
A11: 46109 | B11: S002 | C11: 성남점 | D11: P003 | E11: 바닐라라떼 | F11: 2 | G11: 4500 | H11: 9000 | I11: 카드 | J11: 김민지 | K11: 판매 | M11: =_xlfn.XLOOKUP(D11,'03_상품Master'!$A$2:$A$11,'03_상품Master'!$C$2:$C$11,"확인필요") -> 커피 | N11: =IF(COUNT(F11:H11)<3, "값확인", IF(F11*G11=H11, "정상", "검토필요")) -> 정상 | O11: =_xlfn.TEXTJOIN("|",FALSE,A11:L11) -> 46109|S002|성남점|P003|바닐라라떼|2|4500|9000|카드|김민지|판매| | P11: =IF(COUNTIF(O11:O300,O11)>1,"중복", "") | Q11: =IFERROR(IF(ISNUMBER(A11), A11,DATEVALUE(SUBSTITUTE(A11,".","-")))," 확인필요") -> 46109
A12: 46136 | B12: S002 | C12: 성남점 | D12: P003 | E12: 바닐라라떼 | F12: 5 | G12: 4500 | H12: 22500 | I12: 현금 | J12: 박서연 | K12: 판매 | M12: =_xlfn.XLOOKUP(D12,'03_상품Master'!$A$2:$A$11,'03_상품Master'!$C$2:$C$11,"확인필요") -> 커피 | N12: =IF(COUNT(F12:H12)<3, "값확인", IF(F12*G12=H12, "정상", "검토필요")) -> 정상 | O12: =_xlfn.TEXTJOIN("|",FALSE,A12:L12) -> 46136|S002|성남점|P003|바닐라라떼|5|4500|22500|현금|박서연|판매| | P12: =IF(COUNTIF(O12:O301,O12)>1,"중복", "") | Q12: =IFERROR(IF(ISNUMBER(A12), A12,DATEVALUE(SUBSTITUTE(A12,".","-")))," 확인필요") -> 46136
A13: 46150 | B13: S002 | C13: 성남점 | D13: P009 | E13: 샌드위치 | F13: 4 | G13: 5500 | H13: 22000 | I13: 현금 | J13: 박서연 | K13: 판매 | M13: =_xlfn.XLOOKUP(D13,'03_상품Master'!$A$2:$A$11,'03_상품Master'!$C$2:$C$11,"확인필요") -> 푸드 | N13: =IF(COUNT(F13:H13)<3, "값확인", IF(F13*G13=H13, "정상", "검토필요")) -> 정상 | O13: =_xlfn.TEXTJOIN("|",FALSE,A13:L13) -> 46150|S002|성남점|P009|샌드위치|4|5500|22000|현금|박서연|판매| | P13: =IF(COUNTIF(O13:O302,O13)>1,"중복", "") | Q13: =IFERROR(IF(ISNUMBER(A13), A13,DATEVALUE(SUBSTITUTE(A13,".","-")))," 확인필요") -> 46150
A14: 46103 | B14: S001 | C14: 신구점 | D14: P001 | E14: 아메리카노 | F14: 1 | G14: 3000 | H14: 3000 | I14: 간편결제 | J14: 김민지 | K14: 판매 | M14: =_xlfn.XLOOKUP(D14,'03_상품Master'!$A$2:$A$11,'03_상품Master'!$C$2:$C$11,"확인필요") -> 커피 | N14: =IF(COUNT(F14:H14)<3, "값확인", IF(F14*G14=H14, "정상", "검토필요")) -> 정상 | O14: =_xlfn.TEXTJOIN("|",FALSE,A14:L14) -> 46103|S001|신구점|P001|아메리카노|1|3000|3000|간편결제|김민지|판매| | P14: =IF(COUNTIF(O14:O303,O14)>1,"중복", "") | Q14: =IFERROR(IF(ISNUMBER(A14), A14,DATEVALUE(SUBSTITUTE(A14,".","-")))," 확인필요") -> 46103
A15: 46144 | B15: S001 | C15: 신구점 | D15: P002 | E15: 카페라떼 | F15: 2 | G15: 4000 | H15: 8000 | I15: 간편결제 | J15: 김민지 | K15: 판매 | M15: =_xlfn.XLOOKUP(D15,'03_상품Master'!$A$2:$A$11,'03_상품Master'!$C$2:$C$11,"확인필요") -> 커피 | N15: =IF(COUNT(F15:H15)<3, "값확인", IF(F15*G15=H15, "정상", "검토필요")) -> 정상 | O15: =_xlfn.TEXTJOIN("|",FALSE,A15:L15) -> 46144|S001|신구점|P002|카페라떼|2|4000|8000|간편결제|김민지|판매| | P15: =IF(COUNTIF(O15:O304,O15)>1,"중복", "") | Q15: =IFERROR(IF(ISNUMBER(A15), A15,DATEVALUE(SUBSTITUTE(A15,".","-")))," 확인필요") -> 46144
A16: 46125 | B16: S001 | C16: 신구점 | D16: P004 | E16: 카라멜마끼아또 | F16: 2 | G16: 4800 | H16: 9600 | I16: 현금 | J16: 정다은 | K16: 취소 | M16: =_xlfn.XLOOKUP(D16,'03_상품Master'!$A$2:$A$11,'03_상품Master'!$C$2:$C$11,"확인필요") -> 커피 | N16: =IF(COUNT(F16:H16)<3, "값확인", IF(F16*G16=H16, "정상", "검토필요")) -> 정상 | O16: =_xlfn.TEXTJOIN("|",FALSE,A16:L16) -> 46125|S001|신구점|P004|카라멜마끼아또|2|4800|9600|현금|정다은|취소| | P16: =IF(COUNTIF(O16:O305,O16)>1,"중복", "") | Q16: =IFERROR(IF(ISNUMBER(A16), A16,DATEVALUE(SUBSTITUTE(A16,".","-")))," 확인필요") -> 46125
A17: 46131 | B17: S001 | C17: 신구점 | D17: P001 | E17: 아메리카노 | F17: 3 | G17: 3000 | H17: 9000 | I17: 현금 | J17: 박서연 | K17: 판매 | M17: =_xlfn.XLOOKUP(D17,'03_상품Master'!$A$2:$A$11,'03_상품Master'!$C$2:$C$11,"확인필요") -> 커피 | N17: =IF(COUNT(F17:H17)<3, "값확인", IF(F17*G17=H17, "정상", "검토필요")) -> 정상 | O17: =_xlfn.TEXTJOIN("|",FALSE,A17:L17) -> 46131|S001|신구점|P001|아메리카노|3|3000|9000|현금|박서연|판매| | P17: =IF(COUNTIF(O17:O306,O17)>1,"중복", "") | Q17: =IFERROR(IF(ISNUMBER(A17), A17,DATEVALUE(SUBSTITUTE(A17,".","-")))," 확인필요") -> 46131
A18: 46165 | B18: S001 | C18: 신구점 | D18: P010 | E18: 베이글 | F18: 2 | G18: 4000 | H18: 8000 | I18: 카드 | J18: 박서연 | K18: 판매 | M18: =_xlfn.XLOOKUP(D18,'03_상품Master'!$A$2:$A$11,'03_상품Master'!$C$2:$C$11,"확인필요") -> 푸드 | N18: =IF(COUNT(F18:H18)<3, "값확인", IF(F18*G18=H18, "정상", "검토필요")) -> 정상 | O18: =_xlfn.TEXTJOIN("|",FALSE,A18:L18) -> 46165|S001|신구점|P010|베이글|2|4000|8000|카드|박서연|판매| | P18: =IF(COUNTIF(O18:O307,O18)>1,"중복", "") | Q18: =IFERROR(IF(ISNUMBER(A18), A18,DATEVALUE(SUBSTITUTE(A18,".","-")))," 확인필요") -> 46165
A19: 46160 | B19: S002 | C19: 성남점 | D19: P001 | E19: 아메리카노 | F19: 1 | G19: 3000 | H19: 3000 | I19: 간편결제 | J19: 최지훈 | K19: 판매 | M19: =_xlfn.XLOOKUP(D19,'03_상품Master'!$A$2:$A$11,'03_상품Master'!$C$2:$C$11,"확인필요") -> 커피 | N19: =IF(COUNT(F19:H19)<3, "값확인", IF(F19*G19=H19, "정상", "검토필요")) -> 정상 | O19: =_xlfn.TEXTJOIN("|",FALSE,A19:L19) -> 46160|S002|성남점|P001|아메리카노|1|3000|3000|간편결제|최지훈|판매| | P19: =IF(COUNTIF(O19:O308,O19)>1,"중복", "") | Q19: =IFERROR(IF(ISNUMBER(A19), A19,DATEVALUE(SUBSTITUTE(A19,".","-")))," 확인필요") -> 46160
A20: 46126 | B20: S001 | C20: 신구점 | D20: P004 | E20: 카라멜마끼아또 | F20: 4 | G20: 4800 | H20: 19200 | I20: 현금 | K20: 판매 | M20: =_xlfn.XLOOKUP(D20,'03_상품Master'!$A$2:$A$11,'03_상품Master'!$C$2:$C$11,"확인필요") -> 커피 | N20: =IF(COUNT(F20:H20)<3, "값확인", IF(F20*G20=H20, "정상", "검토필요")) -> 정상 | O20: =_xlfn.TEXTJOIN("|",FALSE,A20:L20) -> 46126|S001|신구점|P004|카라멜마끼아또|4|4800|19200|현금||판매| | P20: =IF(COUNTIF(O20:O309,O20)>1,"중복", "") | Q20: =IFERROR(IF(ISNUMBER(A20), A20,DATEVALUE(SUBSTITUTE(A20,".","-")))," 확인필요") -> 46126
A21: 46138 | B21: S003 | C21: 용인점 | D21: P008 | E21: 크루아상 | F21: 2 | G21: 3500 | H21: 7000 | I21: 카드 | J21: 최지훈 | K21: 판매 | M21: =_xlfn.XLOOKUP(D21,'03_상품Master'!$A$2:$A$11,'03_상품Master'!$C$2:$C$11,"확인필요") -> 디저트 | N21: =IF(COUNT(F21:H21)<3, "값확인", IF(F21*G21=H21, "정상", "검토필요")) -> 정상 | O21: =_xlfn.TEXTJOIN("|",FALSE,A21:L21) -> 46138|S003|용인점|P008|크루아상|2|3500|7000|카드|최지훈|판매| | P21: =IF(COUNTIF(O21:O310,O21)>1,"중복", "") | Q21: =IFERROR(IF(ISNUMBER(A21), A21,DATEVALUE(SUBSTITUTE(A21,".","-")))," 확인필요") -> 46138
A22: 46141 | B22: S003 | C22: 용인점 | D22: P005 | E22: 녹차라떼 | F22: 1 | G22: 4500 | H22: 4500 | I22: 간편결제 | J22: 최지훈 | K22: 판매 | M22: =_xlfn.XLOOKUP(D22,'03_상품Master'!$A$2:$A$11,'03_상품Master'!$C$2:$C$11,"확인필요") -> 논커피 | N22: =IF(COUNT(F22:H22)<3, "값확인", IF(F22*G22=H22, "정상", "검토필요")) -> 정상 | O22: =_xlfn.TEXTJOIN("|",FALSE,A22:L22) -> 46141|S003|용인점|P005|녹차라떼|1|4500|4500|간편결제|최지훈|판매| | P22: =IF(COUNTIF(O22:O311,O22)>1,"중복", "") | Q22: =IFERROR(IF(ISNUMBER(A22), A22,DATEVALUE(SUBSTITUTE(A22,".","-")))," 확인필요") -> 46141
A23: 46133 | B23: S003 | C23: 용인점 | D23: P001 | E23: 아메리카노 | F23: 1 | G23: 3000 | H23: 3000 | I23: 카드 | J23: 김민지 | K23: 판매 | M23: =_xlfn.XLOOKUP(D23,'03_상품Master'!$A$2:$A$11,'03_상품Master'!$C$2:$C$11,"확인필요") -> 커피 | N23: =IF(COUNT(F23:H23)<3, "값확인", IF(F23*G23=H23, "정상", "검토필요")) -> 정상 | O23: =_xlfn.TEXTJOIN("|",FALSE,A23:L23) -> 46133|S003|용인점|P001|아메리카노|1|3000|3000|카드|김민지|판매| | P23: =IF(COUNTIF(O23:O312,O23)>1,"중복", "") | Q23: =IFERROR(IF(ISNUMBER(A23), A23,DATEVALUE(SUBSTITUTE(A23,".","-")))," 확인필요") -> 46133
A24: 46130 | B24: S001 | C24: 신구점 | D24: P002 | E24: 카페라떼 | F24: 2 | G24: 4000 | H24: 8000 | I24: 카드 | J24: 한지우 | K24: 판매 | M24: =_xlfn.XLOOKUP(D24,'03_상품Master'!$A$2:$A$11,'03_상품Master'!$C$2:$C$11,"확인필요") -> 커피 | N24: =IF(COUNT(F24:H24)<3, "값확인", IF(F24*G24=H24, "정상", "검토필요")) -> 정상 | O24: =_xlfn.TEXTJOIN("|",FALSE,A24:L24) -> 46130|S001|신구점|P002|카페라떼|2|4000|8000|카드|한지우|판매| | P24: =IF(COUNTIF(O24:O313,O24)>1,"중복", "") | Q24: =IFERROR(IF(ISNUMBER(A24), A24,DATEVALUE(SUBSTITUTE(A24,".","-")))," 확인필요") -> 46130
A25: 46141 | B25: S001 | C25: 신구점 | D25: P001 | E25: 아메리카노 | F25: 2 | G25: 3000 | H25: 6000 | I25: 간편결제 | J25: 박서연 | K25: 판매 | M25: =_xlfn.XLOOKUP(D25,'03_상품Master'!$A$2:$A$11,'03_상품Master'!$C$2:$C$11,"확인필요") -> 커피 | N25: =IF(COUNT(F25:H25)<3, "값확인", IF(F25*G25=H25, "정상", "검토필요")) -> 정상 | O25: =_xlfn.TEXTJOIN("|",FALSE,A25:L25) -> 46141|S001|신구점|P001|아메리카노|2|3000|6000|간편결제|박서연|판매| | P25: =IF(COUNTIF(O25:O314,O25)>1,"중복", "") | Q25: =IFERROR(IF(ISNUMBER(A25), A25,DATEVALUE(SUBSTITUTE(A25,".","-")))," 확인필요") -> 46141
A26: 46149 | B26: S001 | C26: 신구점 | D26: P007 | E26: 치즈케이크 | F26: 2 | G26: 5000 | H26: 10000 | I26: 간편결제 | J26: 김민지 | K26: 취소 | M26: =_xlfn.XLOOKUP(D26,'03_상품Master'!$A$2:$A$11,'03_상품Master'!$C$2:$C$11,"확인필요") -> 디저트 | N26: =IF(COUNT(F26:H26)<3, "값확인", IF(F26*G26=H26, "정상", "검토필요")) -> 정상 | O26: =_xlfn.TEXTJOIN("|",FALSE,A26:L26) -> 46149|S001|신구점|P007|치즈케이크|2|5000|10000|간편결제|김민지|취소| | P26: =IF(COUNTIF(O26:O315,O26)>1,"중복", "") | Q26: =IFERROR(IF(ISNUMBER(A26), A26,DATEVALUE(SUBSTITUTE(A26,".","-")))," 확인필요") -> 46149
A27: 46163 | B27: S002 | C27: 성남점 | D27: P008 | E27: 크루아상 | F27: 2 | G27: 3500 | H27: 7000 | I27: 간편결제 | J27: 정다은 | K27: 취소 | M27: =_xlfn.XLOOKUP(D27,'03_상품Master'!$A$2:$A$11,'03_상품Master'!$C$2:$C$11,"확인필요") -> 디저트 | N27: =IF(COUNT(F27:H27)<3, "값확인", IF(F27*G27=H27, "정상", "검토필요")) -> 정상 | O27: =_xlfn.TEXTJOIN("|",FALSE,A27:L27) -> 46163|S002|성남점|P008|크루아상|2|3500|7000|간편결제|정다은|취소| | P27: =IF(COUNTIF(O27:O316,O27)>1,"중복", "") | Q27: =IFERROR(IF(ISNUMBER(A27), A27,DATEVALUE(SUBSTITUTE(A27,".","-")))," 확인필요") -> 46163
A28: 46095 | B28: S003 | C28: 용인점 | D28: P007 | E28: 치즈케이크 | F28: 4 | G28: 5000 | H28: 20000 | I28: 현금 | J28: 정다은 | K28: 판매 | M28: =_xlfn.XLOOKUP(D28,'03_상품Master'!$A$2:$A$11,'03_상품Master'!$C$2:$C$11,"확인필요") -> 디저트 | N28: =IF(COUNT(F28:H28)<3, "값확인", IF(F28*G28=H28, "정상", "검토필요")) -> 정상 | O28: =_xlfn.TEXTJOIN("|",FALSE,A28:L28) -> 46095|S003|용인점|P007|치즈케이크|4|5000|20000|현금|정다은|판매| | P28: =IF(COUNTIF(O28:O317,O28)>1,"중복", "") | Q28: =IFERROR(IF(ISNUMBER(A28), A28,DATEVALUE(SUBSTITUTE(A28,".","-")))," 확인필요") -> 46095
A29: 46115 | B29: S002 | C29: 성남점 | D29: P004 | E29: 카라멜마끼아또 | F29: 3 | G29: 4800 | H29: 14400 | I29: 간편결제 | J29: 김민지 | K29: 판매 | M29: =_xlfn.XLOOKUP(D29,'03_상품Master'!$A$2:$A$11,'03_상품Master'!$C$2:$C$11,"확인필요") -> 커피 | N29: =IF(COUNT(F29:H29)<3, "값확인", IF(F29*G29=H29, "정상", "검토필요")) -> 정상 | O29: =_xlfn.TEXTJOIN("|",FALSE,A29:L29) -> 46115|S002|성남점|P004|카라멜마끼아또|3|4800|14400|간편결제|김민지|판매| | P29: =IF(COUNTIF(O29:O318,O29)>1,"중복", "") | Q29: =IFERROR(IF(ISNUMBER(A29), A29,DATEVALUE(SUBSTITUTE(A29,".","-")))," 확인필요") -> 46115
A30: 46161 | B30: S001 | C30: 신구점 | D30: P001 | E30: 아메리카노 | F30: 2 | G30: 3000 | H30: 6000 | I30: 카드 | J30: 박서연 | K30: 판매 | M30: =_xlfn.XLOOKUP(D30,'03_상품Master'!$A$2:$A$11,'03_상품Master'!$C$2:$C$11,"확인필요") -> 커피 | N30: =IF(COUNT(F30:H30)<3, "값확인", IF(F30*G30=H30, "정상", "검토필요")) -> 정상 | O30: =_xlfn.TEXTJOIN("|",FALSE,A30:L30) -> 46161|S001|신구점|P001|아메리카노|2|3000|6000|카드|박서연|판매| | P30: =IF(COUNTIF(O30:O319,O30)>1,"중복", "") | Q30: =IFERROR(IF(ISNUMBER(A30), A30,DATEVALUE(SUBSTITUTE(A30,".","-")))," 확인필요") -> 46161
A31: 46119 | B31: S002 | C31: 성남점 | D31: P006 | E31: 초코라떼 | F31: 1 | G31: 4500 | H31: 4500 | I31: 현금 | J31: 이서준 | K31: 판매 | M31: =_xlfn.XLOOKUP(D31,'03_상품Master'!$A$2:$A$11,'03_상품Master'!$C$2:$C$11,"확인필요") -> 논커피 | N31: =IF(COUNT(F31:H31)<3, "값확인", IF(F31*G31=H31, "정상", "검토필요")) -> 정상 | O31: =_xlfn.TEXTJOIN("|",FALSE,A31:L31) -> 46119|S002|성남점|P006|초코라떼|1|4500|4500|현금|이서준|판매| | P31: =IF(COUNTIF(O31:O320,O31)>1,"중복", "") | Q31: =IFERROR(IF(ISNUMBER(A31), A31,DATEVALUE(SUBSTITUTE(A31,".","-")))," 확인필요") -> 46119
A32: 46088 | B32: S002 | C32: 성남점 | D32: P005 | E32: 녹차라떼 | F32: 1 | G32: 4500 | H32: 4500 | I32: 간편결제 | J32: 정다은 | K32: 판매 | M32: =_xlfn.XLOOKUP(D32,'03_상품Master'!$A$2:$A$11,'03_상품Master'!$C$2:$C$11,"확인필요") -> 논커피 | N32: =IF(COUNT(F32:H32)<3, "값확인", IF(F32*G32=H32, "정상", "검토필요")) -> 정상 | O32: =_xlfn.TEXTJOIN("|",FALSE,A32:L32) -> 46088|S002|성남점|P005|녹차라떼|1|4500|4500|간편결제|정다은|판매| | P32: =IF(COUNTIF(O32:O321,O32)>1,"중복", "") | Q32: =IFERROR(IF(ISNUMBER(A32), A32,DATEVALUE(SUBSTITUTE(A32,".","-")))," 확인필요") -> 46088
... A35: 46090 | B35: S003 | C35: 용인점 | D35: P004 | E35: 카라멜마끼아또 | F35: 2 | G35: 4800 | H35: 9600 | I35: 간편결제 | J35: 김민지 | K35: 판매 | M35: =_xlfn.XLOOKUP(D35,'03_상품Master'!$A$2:$A$11,'03_상품Master'!$C$2:$C$11,"확인필요") -> 커피 | N35: =IF(COUNT(F35:H35)<3, "값확인", IF(F35*G35=H35, "정상", "검토필요")) -> 정상 | O35: =_xlfn.TEXTJOIN("|",FALSE,A35:L35) -> 46090|S003|용인점|P004|카라멜마끼아또|2|4800|9600|간편결제|김민지|판매| | P35: =IF(COUNTIF(O35:O324,O35)>1,"중복", "") | Q35: =IFERROR(IF(ISNUMBER(A35), A35,DATEVALUE(SUBSTITUTE(A35,".","-")))," 확인필요") -> 46090
A36: 46149 | B36: S002 | C36: 성남점 | D36: P008 | E36: 크루아상 | F36: 1 | G36: 3500 | H36: 3500 | J36: 최지훈 | K36: 판매 | M36: =_xlfn.XLOOKUP(D36,'03_상품Master'!$A$2:$A$11,'03_상품Master'!$C$2:$C$11,"확인필요") -> 디저트 | N36: =IF(COUNT(F36:H36)<3, "값확인", IF(F36*G36=H36, "정상", "검토필요")) -> 정상 | O36: =_xlfn.TEXTJOIN("|",FALSE,A36:L36) -> 46149|S002|성남점|P008|크루아상|1|3500|3500||최지훈|판매| | P36: =IF(COUNTIF(O36:O325,O36)>1,"중복", "") | Q36: =IFERROR(IF(ISNUMBER(A36), A36,DATEVALUE(SUBSTITUTE(A36,".","-")))," 확인필요") -> 46149
A37: 46168 | B37: S002 | C37: 성남점 | D37: P010 | E37: 베이글 | F37: 1 | G37: 4000 | H37: 4000 | I37: 현금 | J37: 박서연 | K37: 판매 | M37: =_xlfn.XLOOKUP(D37,'03_상품Master'!$A$2:$A$11,'03_상품Master'!$C$2:$C$11,"확인필요") -> 푸드 | N37: =IF(COUNT(F37:H37)<3, "값확인", IF(F37*G37=H37, "정상", "검토필요")) -> 정상 | O37: =_xlfn.TEXTJOIN("|",FALSE,A37:L37) -> 46168|S002|성남점|P010|베이글|1|4000|4000|현금|박서연|판매| | P37: =IF(COUNTIF(O37:O326,O37)>1,"중복", "") | Q37: =IFERROR(IF(ISNUMBER(A37), A37,DATEVALUE(SUBSTITUTE(A37,".","-")))," 확인필요") -> 46168
A38: 46153 | B38: S001 | C38: 신구점 | D38: P010 | E38: 베이글 | F38: 1 | G38: 4000 | H38: 4000 | I38: 카드 | J38: 한지우 | K38: 판매 | M38: =_xlfn.XLOOKUP(D38,'03_상품Master'!$A$2:$A$11,'03_상품Master'!$C$2:$C$11,"확인필요") -> 푸드 | N38: =IF(COUNT(F38:H38)<3, "값확인", IF(F38*G38=H38, "정상", "검토필요")) -> 정상 | O38: =_xlfn.TEXTJOIN("|",FALSE,A38:L38) -> 46153|S001|신구점|P010|베이글|1|4000|4000|카드|한지우|판매| | P38: =IF(COUNTIF(O38:O327,O38)>1,"중복", "") | Q38: =IFERROR(IF(ISNUMBER(A38), A38,DATEVALUE(SUBSTITUTE(A38,".","-")))," 확인필요") -> 46153
A39: 46108 | B39: S001 | C39: 신구점 | D39: P010 | E39: 베이글 | F39: 2 | G39: 4000 | H39: 8000 | I39: 현금 | J39: 박서연 | K39: 취소 | M39: =_xlfn.XLOOKUP(D39,'03_상품Master'!$A$2:$A$11,'03_상품Master'!$C$2:$C$11,"확인필요") -> 푸드 | N39: =IF(COUNT(F39:H39)<3, "값확인", IF(F39*G39=H39, "정상", "검토필요")) -> 정상 | O39: =_xlfn.TEXTJOIN("|",FALSE,A39:L39) -> 46108|S001|신구점|P010|베이글|2|4000|8000|현금|박서연|취소| | P39: =IF(COUNTIF(O39:O328,O39)>1,"중복", "") | Q39: =IFERROR(IF(ISNUMBER(A39), A39,DATEVALUE(SUBSTITUTE(A39,".","-")))," 확인필요") -> 46108
A40: 46090 | B40: S001 | C40: 신구점 | D40: P008 | E40: 크루아상 | F40: 3 | G40: 3500 | H40: 10500 | I40: 간편결제 | J40: 최지훈 | K40: 판매 | M40: =_xlfn.XLOOKUP(D40,'03_상품Master'!$A$2:$A$11,'03_상품Master'!$C$2:$C$11,"확인필요") -> 디저트 | N40: =IF(COUNT(F40:H40)<3, "값확인", IF(F40*G40=H40, "정상", "검토필요")) -> 정상 | O40: =_xlfn.TEXTJOIN("|",FALSE,A40:L40) -> 46090|S001|신구점|P008|크루아상|3|3500|10500|간편결제|최지훈|판매| | P40: =IF(COUNTIF(O40:O329,O40)>1,"중복", "") | Q40: =IFERROR(IF(ISNUMBER(A40), A40,DATEVALUE(SUBSTITUTE(A40,".","-")))," 확인필요") -> 46090
A41: 46163 | B41: S001 | C41: 신구점 | D41: P002 | E41: 카페라떼 | F41: 1 | G41: 4000 | H41: 4000 | I41: 간편결제 | J41: 이서준 | K41: 판매 | M41: =_xlfn.XLOOKUP(D41,'03_상품Master'!$A$2:$A$11,'03_상품Master'!$C$2:$C$11,"확인필요") -> 커피 | N41: =IF(COUNT(F41:H41)<3, "값확인", IF(F41*G41=H41, "정상", "검토필요")) -> 정상 | O41: =_xlfn.TEXTJOIN("|",FALSE,A41:L41) -> 46163|S001|신구점|P002|카페라떼|1|4000|4000|간편결제|이서준|판매| | P41: =IF(COUNTIF(O41:O330,O41)>1,"중복", "") | Q41: =IFERROR(IF(ISNUMBER(A41), A41,DATEVALUE(SUBSTITUTE(A41,".","-")))," 확인필요") -> 46163
A42: 46144 | B42: S003 | C42: 용인점 | D42: P005 | E42: 녹차라떼 | F42: 1 | G42: 4500 | H42: 4500 | I42: 간편결제 | J42: 이서준 | K42: 판매 | M42: =_xlfn.XLOOKUP(D42,'03_상품Master'!$A$2:$A$11,'03_상품Master'!$C$2:$C$11,"확인필요") -> 논커피 | N42: =IF(COUNT(F42:H42)<3, "값확인", IF(F42*G42=H42, "정상", "검토필요")) -> 정상 | O42: =_xlfn.TEXTJOIN("|",FALSE,A42:L42) -> 46144|S003|용인점|P005|녹차라떼|1|4500|4500|간편결제|이서준|판매| | P42: =IF(COUNTIF(O42:O331,O42)>1,"중복", "") | Q42: =IFERROR(IF(ISNUMBER(A42), A42,DATEVALUE(SUBSTITUTE(A42,".","-")))," 확인필요") -> 46144
...

Sheet 06_피벗분석
A1: 주문상태 | B1: 판매
A3: 합계 : 매출액 | B3: 열 레이블
A4: 행 레이블 | B4: 3월 | C4: 4월 | D4: 5월 | E4: 총합계
A5: 성남점 | B5: 204700 | C5: 321600 | D5: 219300 | E5: 745600
A6: 신구점 | B6: 298300 | C6: 372200 | D6: 359200 | E6: 1029700
A7: 용인점 | B7: 246500 | C7: 167500 | D7: 176500 | E7: 590500
A8: 총합계 | B8: 749500 | C8: 861300 | D8: 755000 | E8: 2365800

Sheet 07_대시보드
A1: 학생 작업용

Sheet 08_AI보고서
B2: 1. 현황: 3~5월 판매 매출은 총 2,365,800원이며, 4월이 861,300원으로 가장 높고 5월은 755,000원으로 감소했습니다.
B3: 2. 인사이트: 누적 매출은 신구점(1,029,700원) > 성남점(745,600원) > 용인점(590,500원) 순이며, 신구점은 매월 가장 높은 매출을 기록했습니다.
B4: 2. 인사이트: 4월→5월에는 성남점 -102,300원, 신구점 -13,000원, 용인점 +9,000원으로 지점별 매출 변화가 다르게 나타났습니다.
B5: 3. 추가 확인사항 / 실행 과제: 추가 확인 필요 — 지점별 매출 변화가 어떤 상품분류와 판매수량·판매건수에서 발생했는지 세부 분석합니다.
B6: 3. 추가 확인사항 / 실행 과제: 특히 4월→5월 성남점의 감소와 용인점의 증가 내역을 상품분류별로 추가 확인합니다.

Sheet 09_함수테스트
A1: 09_함수테스트 — AI가 만든 수식을 작은 데이터로 먼저 검증하기
A2: 학습 원칙: AI에게 수식을 요청 → 10행 내외의 테스트 데이터에서 확인 → 이상 없을 때 실제 300행 데이터에 적용
A4: ① IF 함수 테스트 — 수량 × 판매단가와 매출액 일치 여부 확인
A5: 수량 | B5: 판매단가 | C5: 매출액 | D5: 판정(수식 입력) | E5: 예상 결과 | F5: 검증
A6: 2 | B6: 4000 | C6: 8000 | D6: =IF(A6*B6=C6,"정상","검토") -> 정상 | E6: 정상 | F6: 직접 확인
A7: 3 | B7: 4500 | C7: 13000 | D7: =IF(A7*B7=C7,"정상","검토") -> 검토 | E7: 검토필요 | F7: 직접 확인
A8: 1 | B8: 3000 | C8: 3000 | D8: =IF(A8*B8=C8,"정상","검토") -> 정상 | E8: 정상 | F8: 직접 확인
A9: 4 | B9: 4800 | C9: 19200 | D9: =IF(A9*B9=C9,"정상","검토") -> 정상 | E9: 정상 | F9: 직접 확인
A10: 2 | B10: 3500 | C10: 6000 | D10: =IF(A10*B10=C10,"정상","검토") -> 검토 | E10: 검토필요 | F10: 직접 확인
A11: 5 | B11: 4500 | C11: 22500 | D11: =IF(A11*B11=C11,"정상","검토") -> 정상 | E11: 정상 | F11: 직접 확인
A12: 3 | B12: 5000 | C12: 15000 | D12: =IF(A12*B12=C12,"정상","검토") -> 정상 | E12: 정상 | F12: 직접 확인
A13: 2 | B13: 5500 | C13: 11000 | D13: =IF(A13*B13=C13,"정상","검토") -> 정상 | E13: 정상 | F13: 직접 확인
A14: 4 | B14: 4000 | C14: 15000 | D14: =IF(A14*B14=C14,"정상","검토") -> 검토 | E14: 검토필요 | F14: 직접 확인
A15: 1 | B15: 4500 | C15: 4500 | D15: =IF(A15*B15=C15,"정상","검토") -> 정상 | E15: 정상 | F15: 직접 확인
A18: ② 조회 함수 테스트 — 상품코드로 상품분류 찾기
A19: 상품코드 | B19: 상품분류(수식 입력) | C19: 예상 결과 | D19: 검증 | E19: 확인 포인트
A20: P001 | B20: =_xlfn.XLOOKUP(A20,'03_상품Master'!$A$2:$A$11,'03_상품Master'!$C$2:$C$11,"확인필요") -> 커피 | C20: 커피 | D20: 직접 확인 | E20: 정상 코드
A21: P002 | B21: =_xlfn.XLOOKUP(A21,'03_상품Master'!$A$2:$A$11,'03_상품Master'!$C$2:$C$11,"확인필요") -> 커피 | C21: 커피 | D21: 직접 확인 | E21: 정상 코드
A22: P005 | B22: =_xlfn.XLOOKUP(A22,'03_상품Master'!$A$2:$A$11,'03_상품Master'!$C$2:$C$11,"확인필요") -> 논커피 | C22: 논커피 | D22: 직접 확인 | E22: 정상 코드 | G22: =TRIM("카페 라떼") -> 카페 라떼
A23: P007 | B23: =_xlfn.XLOOKUP(A23,'03_상품Master'!$A$2:$A$11,'03_상품Master'!$C$2:$C$11,"확인필요") -> 디저트 | C23: 디저트 | D23: 직접 확인 | E23: 정상 코드 | G23: =SUBSTITUTE("카페 라떼", " ","") -> 카페라떼
A24: P009 | B24: =_xlfn.XLOOKUP(A24,'03_상품Master'!$A$2:$A$11,'03_상품Master'!$C$2:$C$11,"확인필요") -> 푸드 | C24: 푸드 | D24: 직접 확인 | E24: 정상 코드
A25: P010 | B25: =_xlfn.XLOOKUP(A25,'03_상품Master'!$A$2:$A$11,'03_상품Master'!$C$2:$C$11,"확인필요") -> 푸드 | C25: 푸드 | D25: 직접 확인 | E25: 정상 코드
A26: P013 | B26: =_xlfn.XLOOKUP(A26,'03_상품Master'!$A$2:$A$11,'03_상품Master'!$C$2:$C$11,"확인필요") -> 확인필요 | C26: 확인필요 | D26: 직접 확인 | E26: Master에 없는 코드
A27: P003 | B27: =_xlfn.XLOOKUP(A27,'03_상품Master'!$A$2:$A$11,'03_상품Master'!$C$2:$C$11,"확인필요") -> 커피 | C27: 커피 | D27: 직접 확인 | E27: 정상 코드
A28: P008 | B28: =_xlfn.XLOOKUP(A28,'03_상품Master'!$A$2:$A$11,'03_상품Master'!$C$2:$C$11,"확인필요") -> 디저트 | C28: 디저트 | D28: 직접 확인 | E28: 정상 코드
A29: P011 | B29: =_xlfn.XLOOKUP(A29,'03_상품Master'!$A$2:$A$11,'03_상품Master'!$C$2:$C$11,"확인필요") -> 확인필요 | C29: 확인필요 | D29: 직접 확인 | E29: Master에 없는 코드
A31: ③ SUMIFS 테스트 — 조건을 여러 개 적용해 합계하기 | I31: ▶ 조건 입력 칸을 참조해 SUMIFS 수식을 만드세요 (M열에 입력)
A32: 월 | B32: 지점명 | C32: 주문상태 | D32: 매출액 | I32: 문제 | J32: 월 | K32: 지점명 | L32: 주문상태 | M32: SUMIFS 결과 (수식 입력) | N32: 예상 결과 | O32: 실제 매출 (표를 보고 직접 계산)
A33: 3월 | B33: 신구점 | C33: 판매 | D33: 8000 | I33: Q1. 3월 신구점 판매 매출 | J33: 3월 | K33: 신구점 | L33: 판매 | M33: =SUMIFS($D$33:$D$42,$A$33:$A$42,J33,$B$33:$B$42,K33,$C$33:$C$42,L33) -> 14000 | N33: 14000 | O33: 21000
A34: 3월 | B34: 신구점 | C34: 판매 | D34: 6000 | I34: Q2. 4월 성남점 판매 매출 | J34: 4월 | K34: 성남점 | L34: 판매 | M34: =SUMIFS($D$33:$D$42,$A$33:$A$42,J34,$B$33:$B$42,K34,$C$33:$C$42,L34) -> 9000 | N34: 9000 | O34: 9000
A35: 3월 | B35: 성남점 | C35: 판매 | D35: 5000 | I35: Q3. 5월 용인점 판매 매출 | J35: 5월 | K35: 용인점 | L35: 판매 | M35: =SUMIFS($D$33:$D$42,$A$33:$A$42,J35,$B$33:$B$42,K35,$C$33:$C$42,L35) -> 12000 | N35: 12000 | O35: 17000
A36: 3월 | B36: 신구 점 | C36: 판매 | D36: 7000 | I36: Q4. 신구점 판매 매출 (월 조건 없음) | J36: (조건 없음) | K36: 신구점 | L36: 판매 | M36: =SUMIFS($D$33:$D$42,$A$33:$A$42,J36,$B$33:$B$42,K36,$C$33:$C$42,L36) -> 0 | N36: 14000 | O36: 29000
A37: 4월 | B37: 성남점 | C37: 판매 | D37: 9000
A38: 4월 | B38: 성남점 | C38: 취소 | D38: 3000 | I38: 생각해보기: M열(SUMIFS 결과)과 O열(직접 계산)이 다른 문제는? 수식은 오류 없이 실행됐는데 왜 값이 다를까요?
A39: 4월 | B39: 용인점 | C39: 판매 | D39: 10000
A40: 5월 | B40: 용인점 | C40: 판매 | D40: 12000
A41: 5월 | B41: 용인 점 | C41: 판매 | D41: 5000
A42: 5월 | B42: 신구점 | C42: 판매 | D42: 8,000
A44: ④ 데이터 품질 미니 점검 — 날짜·지점명·숫자 표기 차이까지 찾아보기
A45: 주문일자 | B45: 지점명 | C45: 상품코드 | D45: 수량 | E45: 판매단가 | F45: 매출액 | G45: 학생이 찾은 문제 | H45: 처리/표준화
...

Sheet 10_확인필요
A1: 10_확인필요 — 분석에서 제외한 행을 사유와 함께 기록하기 (강사 시연)
A2: 사용법: ① 05 시트 → 색 기준 필터(연한 빨강) ② 보이는 행의 A~L만 선택해 Ctrl+C ③ 이 시트 A5에 붙여넣기 ④ M열에 제외 사유 입력 ⑤ 05 시트로 돌아가 PART 04에서 3행 삭제
A3: 원칙: 분석에서 뺀다 ≠ 버린다. 원본은 「02_매출원본」에 그대로 있고, 이 목록은 담당자 확인용입니다. (M~Q 도우미 열은 복사하지 않습니다)
A4: 주문일자 | B4: 지점코드 | C4: 지점명 | D4: 상품코드 | E4: 상품명 | F4: 수량 | G4: 판매단가 | H4: 매출액 | I4: 결제수단 | J4: 담당자 | K4: 주문상태 | L4: 비고 | M4: 제외 사유 | N4: 담당자 확인 결과
A5: 46104 | B5: S002 | C5: 성남점 | D5: P001 | E5: 아메리카노 | G5: 3000 | H5: 3000 | I5: 카드 | J5: 이서준 | K5: 판매 | M5: 수량 빈칸
A6: 확인필요 | B6: S001 | C6: 신구점 | D6: P001 | E6: 아메리카노 | F6: 1 | G6: 3000 | H6: 3000 | I6: 현금 | J6: 이서준 | K6: 판매 | M6: 주문일자 빈칸
A7: 46165 | B7: S002 | C7: 성남점 | D7: P003 | E7: 바닐라라떼 | F7: 2 | G7: 4500 | H7: 9000 | I7: 간편결제 | J7: 최지훈 | M7: 주문상태 빈칸
A11: 확인 포인트
A12: • 붙여넣으면 3행이 들어와야 합니다 — 원본 8행(수량 빈칸), 118행(주문일자 빈칸), 224행(주문상태 빈칸)
A13: • 05 시트 기준으로는 8행, 115행, 219행입니다 (불필요한 행·중복 삭제로 행 번호가 바뀜)
A14: • N열 「담당자 확인 결과」는 비워 두고, 실무에서는 담당자 답변을 받아 기록합니다
